/*
 *  Copyright 2018 TWO SIGMA OPEN SOURCE, LLC
 *
 *  Licensed under the Apache License, Version 2.0 (the "License");
 *  you may not use this file except in compliance with the License.
 *  You may obtain a copy of the License at
 *
 *    http://www.apache.org/licenses/LICENSE-2.0
 *
 *  Unless required by applicable law or agreed to in writing, software
 *  distributed under the License is distributed on an "AS IS" BASIS,
 *  WITHOUT WARRANTIES OR CONDITIONS OF ANY KIND, either express or implied.
 *  See the License for the specific language governing permissions and
 *  limitations under the License.
 */

package com.twosigma.flint.util

/**
 * Copied from org.apache.spark.util.Utils
 */

object Utils {
  /**
   * Execute a block of code, then a finally block, but if exceptions happen in
   * the finally block, do not suppress the original exception.
   *
   * This is primarily an issue with `finally { out.close() }` blocks, where
   * close needs to be called to clean up `out`, but if an exception happened
   * in `out.write`, it's likely `out` may be corrupted and `out.close` will
   * fail as well. This would then suppress the original/likely more meaningful
   * exception from the original `out.write` call.
   */
  def tryWithSafeFinally[T](block: => T)(finallyBlock: => Unit): T = {
    var originalThrowable: Throwable = null
    try {
      block
    } catch {
      case t: Throwable =>
        // Purposefully not using NonFatal, because even fatal exceptions
        // we don't want to have our finallyBlock suppress
        originalThrowable = t
        throw originalThrowable
    } finally {
      try {
        finallyBlock
      } catch {
        case t: Throwable =>
          if (originalThrowable != null) {
            originalThrowable.addSuppressed(t)
            // logWarning(s"Suppressing exception in finally: " + t.getMessage, t)
            throw originalThrowable
          } else {
            throw t
          }
      }
    }
  }
}

